<?xml version="1.0"?>
<robot name="my_robot">

  <link name="base_link">
  </link>

  <link name="box_link">
    <visual>
      <origin xyz="0.15 0.0 0.075"/>
      <geometry>
        <box size="0.3 0.3 0.15"/>
      </geometry>
      <material name="box">
        <color rgba="1.0 1.0 1.0 1.0"/>
      </material>
    </visual>
    <collision>
      <origin xyz="0.15 0.0 0.075"/>
      <geometry>
        <box size="0.3 0.3 0.15"/>
      </geometry>
    </collision>
  
    <inertial>
      <origin xyz="0.15 0.0 0.075" rpy="0 0 0"/>
      <mass value="2.0"/>
      <inertia ixx="0.01875" ixy="0.0" ixz="0.0"
               iyy="0.01875" iyz="0.0"
               izz="0.03"/>
    </inertial>
  </link>

  <joint name="base" type="fixed">
    <parent link="base_link"/>
    <child link="box_link"/>
    <origin xyz="-0.1 0.0 0.0"/>
  </joint>

  <link name="camera_link">
  <visual>
    <origin xyz="0.0 0.0 0.0"/>
    <geometry>
      <box size="0.02 0.05 0.05"/>
    </geometry>
    <material name="camera">
        <color rgba="0.0 0.0 0.0 1.0"/>
      </material>
  </visual>

  <collision>
    <origin xyz="0 0 0"/>
    <geometry>
      <box size="0.02 0.05 0.05"/>
    </geometry>
  </collision>

  <inertial>
  <mass value="0.01"/>
  <inertia ixx="1e-5" ixy="0" ixz="0" iyy="1e-5" iyz="0" izz="1e-5"/>
</inertial>

  </link>


  <joint name="camera_joint" type="fixed">
    <parent link="box_link"/>
    <child link="camera_link"/>
    <origin xyz="0.32 0.0 0.075"/>
  </joint>
  <joint name="camera_optical_joint" type="fixed">
    <parent link="camera_link"/>
    <child link="camera_link_optical"/>
    <origin xyz="0.0 0.0 0.0" rpy="-1.5708 0 -1.5708"/>
  </joint>

  <link name="camera_link_optical">
  </link>


<gazebo reference="camera_link">
  <sensor name="camera" type="camera">

    <always_on>true</always_on>
    <visualize>true</visualize>
    <update_rate>30</update_rate>
    <topic>camera/image</topic>

    <camera>
      <horizontal_fov>1.396</horizontal_fov>

      <image>
        <width>640</width>
        <height>480</height>
        <format>R8G8B8</format>
      </image>

      <clip>
        <near>0.1</near>
        <far>100.0</far>
      </clip>

    </camera>

  </sensor>
</gazebo>

  <link name="left_wheel_link">
    <visual>
      <geometry>
        <cylinder radius="0.05" length="0.04"/>
      </geometry>
      <material name="blue">
        <color rgba="0.0 0.0 1.0 1.0"/>
      </material>
    </visual>
    <collision>
      <geometry>
        <cylinder radius="0.05" length="0.04"/>
      </geometry>
    </collision>
    <inertial>
      <origin xyz="0 0 0" rpy="0 0 0"/>
      <mass value="0.2"/>
      <inertia ixx="0.000151666667" ixy="0.0" ixz="0.0"
               iyy="0.000151666667" iyz="0.0"
               izz="0.00025"/>
    </inertial>
  </link>

  <joint name="left_wheel_joint" type="continuous">
    <parent link="base_link"/>
    <child link="left_wheel_link"/>
    <origin xyz="0.0 0.175 0.0" rpy="-1.57 0.0 0.0"/>
    <axis xyz="0.0 0.0 1.0"/>
  </joint>

  <link name="right_wheel_link">
    <visual>
      <geometry>
        <cylinder radius="0.05" length="0.04"/>
      </geometry>
      <material name="blue">
        <color rgba="0.0 0.0 1.0 1.0"/>
      </material>
    </visual>
    <collision>
      <geometry>
        <cylinder radius="0.05" length="0.04"/>
      </geometry>
    </collision>
    <inertial>
      <origin xyz="0 0 0" rpy="0 0 0"/>
      <mass value="0.2"/>
      <inertia ixx="0.000151666667" ixy="0.0" ixz="0.0"
               iyy="0.000151666667" iyz="0.0"
               izz="0.00025"/>
    </inertial>
  </link>

  <joint name="right_wheel_joint" type="continuous">
    <parent link="base_link"/>
    <child link="right_wheel_link"/>
    <origin xyz="0.0 -0.175 0.0" rpy="-1.57 0.0 0.0"/>
    <axis xyz="0.0 0.0 1.0"/>
  </joint>

  <link name="caster_wheel">
    <visual>
      <geometry>
        <sphere radius="0.05"/>
      </geometry>
      <material name="caster_wheel">
        <color rgba="0.0 0.0 0.0 1.0"/>
      </material>
    </visual>
    <collision>
      <geometry>
        <sphere radius="0.05"/>
      </geometry>
    </collision>
    <inertial>
      <origin xyz="0 0 0" rpy="0 0 0"/>
      <mass value="0.1"/>
      <inertia ixx="0.0001" ixy="0.0" ixz="0.0"
               iyy="0.0001" iyz="0.0"
               izz="0.0001"/>
    </inertial>
  </link>

  <joint name="caster_joint" type="fixed">
    <parent link="box_link"/>
    <child link="caster_wheel"/>
    <origin xyz="0.24 0.0 0.0"/>
  </joint>

<gazebo reference="box_link">
  <material>Gazebo/White</material>
</gazebo>

<gazebo reference="left_wheel_link">
  <material>Gazebo/Blue</material>
</gazebo>

<gazebo reference="right_wheel_link">
  <material>Gazebo/Blue</material>
</gazebo>

<gazebo reference="camera_link">
  <material>Gazebo/Black</material>
</gazebo>

<gazebo reference="caster_wheel">
  <material>Gazebo/Black</material>
  <mu1 value="0.001"/>
  <mu2 value="0.001"/>
</gazebo>

  <gazebo>
    <plugin filename="libgz-sim-diff-drive-system.so"
            name="gz::sim::systems::DiffDrive">
      <left_joint>left_wheel_joint</left_joint>
      <right_joint>right_wheel_joint</right_joint>
      <wheel_separation>0.35</wheel_separation>
      <wheel_radius>0.05</wheel_radius>
      <odom_publish_frequency>50</odom_publish_frequency>
      <topic>/cmd_vel</topic>
      <odom_topic>/odom</odom_topic>
      <odom_frame>odom</odom_frame>
      <frame_id>odom</frame_id>
      <child_frame_id>base_link</child_frame_id>
      <publish_odom>true</publish_odom>
      <publish_tf>true</publish_tf>
      <publish_odom_tf>true</publish_odom_tf>
      <publish_wheel_tf>true</publish_wheel_tf>
    </plugin>
     <plugin filename="libgz-sim-joint-state-publisher-system.so"
          name="gz::sim::systems::JointStatePublisher">
          <topic>/joint_states</topic>
  </plugin>
  </gazebo>
<gazebo>
  <plugin
      filename="gz-sim-odometry-publisher-system"
      name="gz::sim::systems::OdometryPublisher">

    <odom_frame>odom</odom_frame>
    <robot_base_frame>base_link</robot_base_frame>
    <odom_topic>/odom</odom_topic>
    <tf_topic>/tf</tf_topic>
    <dimensions>2</dimensions>
    <odom_publish_frequency>10</odom_publish_frequency>

  </plugin>
</gazebo>

</robot>
